Workbook

Sheet Start_Here
B1: Publishing Companion – working file for plan v1.1
B2: Working baseline file for private publishing. Includes 55 book candidates and 20 direct-digital product hypotheses. Existing Beekeeping research is preserved; all other ideas are unvalidated seeds. Example rows are illustrative and must be handled as described.
B4: HOW TO USE IT
B5: 1. Research a niche | C5: Open Research_Routine. Work through the 7 steps (85 minutes) and tick each one.
B6: 2. Score it | C6: Enter what you found on the Scoring sheet: numbers where you measured something, dropdowns where you judged. The total, vetoes and Tier update by themselves.
B7: 3. Decide | C7: Tier 1 = approved for a slot. Tier 2 = re-angle and rescore. Tier 3 or a veto = archive. A niche stays 'Incomplete' until all 12 required inputs are filled.
B8: 4. Publish and log it | C8: When a title goes live, add one row to the Scoreboard. Slot_Ledger then shows how much of each bucket and each weekly limit you've used.
B9: 5. Update monthly | C9: Enter units, returns and net royalty from your KDP reports. The status flag (green, yellow, red) and next action update by themselves.
B10: COLOR LEGEND
B11: Yellow fill, blue text | C11: You fill this in (dropdown or number).
B12: Grey fill, black text | C12: Calculated. Don't overwrite.
B13: Green text | C13: A value linked from the Rubric sheet.
B14: SHEETS
B15: Rubric | C15: Every threshold, price band and dropdown option. Change a value here and everything else follows. Each setting is marked CONFIRMED, REPORTED, VERIFY or PROVISIONAL.
B16: Scoring | C16: One row per Amazon-oriented book candidate, 55 candidates total, with a five-pillar score out of 100, veto logic and Tier. Row 5 is an illustrative example; the existing Beekeeping research row is preserved.
B17: Slot_Ledger | C17: Plan v1.1 ranges against actual paperback titles, yearly usage per format, and this week's two-title limit.
B18: Scoreboard | C18: One row per published title, 50 rows, with return rate, payback days, status flag and next action.
B19: Research_Routine | C19: Seven-step method reference. Use Baseline_Tracker to manage research across all 75 candidate hypotheses.
B20: THINGS TO KNOW BEFORE YOU TRUST IT
B21: Provisional thresholds | C21: Tier cutoffs, stop and winner triggers, and return-rate limits are starting guesses. Calibrate them on your own sales data.
B22: Delivery fee method | C22: How KDP applies the $0.15 per MB fee is not confirmed. The Rubric sheet defaults to the more cautious method; test it with KDP's royalty calculator and set the right one.
B23: No eBook = full points | C23: A niche with no eBook planned earns the full eBook-fee points, since nothing is at risk. This slightly favors paperback-only niches. Change the logic if you disagree.
B24: Judgment dropdowns | C24: Partial-credit options (for example 'Partial' freshness) were added so every score is defined. The original rubric only gave full or zero in several places.
B25: BSR is a proxy | C25: Best-seller rank varies by category and over time. Use it to compare niches, not to predict sales. Calibrate against your own legacy catalog.
B26: Scores are only as good as the evidence | C26: Record what you actually saw in the evidence column. An unverified guess entered as a number produces a confident-looking wrong score.
B27: Candidate_Universe | C27: Full list of 55 book candidates plus 20 direct digital product hypotheses, with intended buyers, product use, cluster links and key questions.
B28: Digital_Product_Research | C28: Dedicated evidence fields for 20 PDF, template, toolkit and design-asset ideas. Use channel-native evidence rather than Amazon BSR.
B29: Baseline_Tracker | C29: Vertical progress tracker for all 75 concepts, including research status, evidence coverage, policy checks and preliminary disposition.
B30: Baseline_Brief | C30: Research instructions, evidence rules, scope, expected report and no-cost bootstrap constraints for the agent.

Sheet Scoring
A1: Niche scoring sheet – one row per candidate niche
A2: Yellow cells with blue text are yours to fill (dropdowns or numbers). Grey cells calculate. Fill all 12 required inputs plus the veto columns; the Tier column then updates by itself. Row 5 is an EXAMPLE with illustrative numbers – delete it once you understand the layout. Evidence columns at the far right are for what you actually saw.
F3: 1. DEMAND & INTENT (25) | M3: 2. COMPETITION & MOAT (25) | U3: 3. UNIT ECONOMICS (20) | AD3: 4. FEASIBILITY (15) | AI3: 5. ECOSYSTEM (15) | AO3: VETOES (any Yes = automatic rejection) | AU3: RESULT & EVIDENCE
A4: # | B4: Niche candidate | C4: Cluster | D4: Product type | E4: Date researched | F4: Avg BSR of top 3 results | G4: BSR pts | H4: Search intent | I4: Intent pts | J4: Freshness signal | K4: Fresh pts | L4: DEMAND /25 | M4: Avg reviews, top 10 | N4: Review pts | O4: Quality defect gap | P4: Defect pts | Q4: Generic look-alike covers (of 48) | R4: Saturation % | S4: Sat. pts | T4: COMPETITION /25 | U4: Net royalty per sale, main format ($) | V4: Royalty pts | W4: eBook list price ($) – optional | X4: eBook file size (MB) – optional | Y4: eBook net royalty ($) | Z4: eBook fee pts | AA4: Return risk | AB4: Return pts | AC4: ECONOMICS /20 | AD4: Production engine fit | AE4: Engine pts | AF4: Editorial accuracy surface | AG4: Editorial pts | AH4: FEASIBILITY /15 | AI4: Cluster potential | AJ4: Cluster pts | AK4: Cross-channel versatility | AL4: Cross pts | AM4: ECOSYSTEM /15 | AN4: TOTAL /100 | AO4: Veto: generic, no specialised use? | AP4: Veto: top 10 entrenched, no defect gap? | AQ4: Veto: KDP guideline or trademark problem? | AR4: Veto: eBook fee (auto) | AS4: Veto: YMYL (auto) | AT4: Veto result | AU4: Inputs missing | AV4: TIER | AW4: Rank | AX4: Next action | AY4: Evidence – what you saw | AZ4: Source links / competitor ASINs
A5: ="Ex." | B5: EXAMPLE – delete this row (illustrative numbers, not research) | C5: Example cluster | D5: Low-content | E5: 46300 | F5: 45000 | G5: =IF(F5="","",VLOOKUP(F5,Rubric!$A$37:$B$40,2,TRUE())) | H5: High – specific problem + buying word | I5: =IF(H5="","",VLOOKUP(H5,Rubric!$A$63:$B$65,2,FALSE())) | J5: Partial – new entrant but weak signals | K5: =IF(J5="","",VLOOKUP(J5,Rubric!$A$69:$B$71,2,FALSE())) | L5: =IF(COUNT(G5,I5,K5)=0,"",SUM(G5,I5,K5)) | M5: 85 | N5: =IF(M5="","",VLOOKUP(M5,Rubric!$A$44:$B$47,2,TRUE())) | O5: Some – 1–2 recurring complaints | P5: =IF(O5="","",VLOOKUP(O5,Rubric!$A$75:$B$77,2,FALSE())) | Q5: 8 | R5: =IF(Q5="","",Q5/Rubric!$B$7) | S5: =IF(R5="","",VLOOKUP(R5,Rubric!$A$51:$B$53,2,TRUE())) | T5: =IF(COUNT(N5,P5,S5)=0,"",SUM(N5,P5,S5)) | U5: 3.2 | V5: =IF(U5="","",VLOOKUP(MAX(U5,0),Rubric!$A$57:$B$59,2,TRUE())) | Y5: =IF(OR(W5="",X5=""),"",IF(AND(W5>=Rubric!$B$8,W5<=Rubric!$B$9),IF(Rubric!$B$13=1,(W5-X5*Rubric!$B$12)*Rubric!$B$10,W5*Rubric!$B$10-X5*Rubric!$B$12),W5*Rubric!$B$11)) | Z5: =IF($B5="","",IF(AND(W5="",X5=""),7,IF(OR(W5="",X5=""),"",IF(X5>Rubric!$B$17,0,IF(AND(Y5>Rubric!$B$14,X5<Rubric!$B$15),7,IF(Y5>Rubric!$B$16,4,0)))))) | AA5: Low – utility log or workbook, <2% | AB5: =IF(AA5="","",VLOOKUP(AA5,Rubric!$A$81:$B$83,2,FALSE())) | AC5: =IF(COUNT(V5,Z5,AB5)=0,"",SUM(V5,Z5,AB5)) | AD5: Full – templatable with the Python generator | AE5: =IF(AD5="","",VLOOKUP(AD5,Rubric!$A$87:$B$89,2,FALSE())) | AF5: Low – logs and forms, little fact-checking | AG5: =IF(AF5="","",VLOOKUP(AF5,Rubric!$A$93:$C$96,2,FALSE())) | AH5: =IF(COUNT(AE5,AG5)=0,"",SUM(AE5,AG5)) | AI5: 3–4 cluster titles | AJ5: =IF(AI5="","",VLOOKUP(AI5,Rubric!$A$100:$B$102,2,FALSE())) | AK5: 2 channels with distinct uses | AL5: =IF(AK5="","",VLOOKUP(AK5,Rubric!$A$106:$B$108,2,FALSE())) | AM5: =IF(COUNT(AJ5,AL5)=0,"",SUM(AJ5,AL5)) | AN5: =IF($B5="","",SUM(L5,T5,AC5,AH5,AM5)) | AO5: No | AP5: No | AQ5: No | AR5: =IF(OR(W5="",X5=""),"",IF(OR(X5>Rubric!$B$19,Y5<Rubric!$B$18),"VETO","")) | AS5: =IF(AF5="","",IF(VLOOKUP(AF5,Rubric!$A$93:$C$96,3,FALSE())="Yes","VETO","")) | AT5: =IF($B5="","",IF(OR(AO5="Yes",AP5="Yes",AQ5="Yes",AR5="VETO",AS5="VETO"),"VETO","")) | AU5: =IF($B5="","",12-COUNTA(F5,H5,J5,M5,O5,Q5,U5,AA5,AD5,AF5,AI5,AK5)+IF(AND(OR(W5="",X5=""),NOT(AND(W5="",X5=""))),1,0)) | AV5: =IF($B5="","",IF(AT5="VETO","Rejected – veto",IF(AU5>0,"Incomplete ("&AU5&" missing)",IF(AN5>=Rubric!$B$5,"Tier 1 – Approved",IF(AN5>=Rubric!$B$6,"Tier 2 – Watchlist","Tier 3 – Rejected"))))) | AW5: – | AX5: Researching | AY5: Example only. Replace with what you saw: competitor titles, the complaints you tallied, price points. | AZ5: Paste competitor links or ASINs here
A6: =IF($B6="","",ROW()-5) | B6: Beekeeping Hive Inspection Log | C6: Beekeeping / Apiculture | D6: Low-content Utility | E6: 46302 | F6: 180000 | G6: =IF(F6="","",VLOOKUP(F6,Rubric!$A$37:$B$40,2,TRUE())) | H6: High – specific problem + buying word | I6: =IF(H6="","",VLOOKUP(H6,Rubric!$A$63:$B$65,2,FALSE())) | J6: Partial – new entrant but weak signals | K6: =IF(J6="","",VLOOKUP(J6,Rubric!$A$69:$B$71,2,FALSE())) | L6: =IF(COUNT(G6,I6,K6)=0,"",SUM(G6,I6,K6)) | M6: 85 | N6: =IF(M6="","",VLOOKUP(M6,Rubric!$A$44:$B$47,2,TRUE())) | O6: Some – 1–2 recurring complaints | P6: =IF(O6="","",VLOOKUP(O6,Rubric!$A$75:$B$77,2,FALSE())) | Q6: 12 | R6: =IF(Q6="","",Q6/Rubric!$B$7) | S6: =IF(R6="","",VLOOKUP(R6,Rubric!$A$51:$B$53,2,TRUE())) | T6: =IF(COUNT(N6,P6,S6)=0,"",SUM(N6,P6,S6)) | U6: 3 | V6: =IF(U6="","",VLOOKUP(MAX(U6,0),Rubric!$A$57:$B$59,2,TRUE())) | Y6: =IF(OR(W6="",X6=""),"",IF(AND(W6>=Rubric!$B$8,W6<=Rubric!$B$9),IF(Rubric!$B$13=1,(W6-X6*Rubric!$B$12)*Rubric!$B$10,W6*Rubric!$B$10-X6*Rubric!$B$12),W6*Rubric!$B$11)) | Z6: =IF($B6="","",IF(AND(W6="",X6=""),7,IF(OR(W6="",X6=""),"",IF(X6>Rubric!$B$17,0,IF(AND(Y6>Rubric!$B$14,X6<Rubric!$B$15),7,IF(Y6>Rubric!$B$16,4,0)))))) | AA6: Low – utility log or workbook, <2% | AB6: =IF(AA6="","",VLOOKUP(AA6,Rubric!$A$81:$B$83,2,FALSE())) | AC6: =IF(COUNT(V6,Z6,AB6)=0,"",SUM(V6,Z6,AB6)) | AD6: Full – templatable with the Python generator | AE6: =IF(AD6="","",VLOOKUP(AD6,Rubric!$A$87:$B$89,2,FALSE())) | AF6: Low – logs and forms, little fact-checking | AG6: =IF(AF6="","",VLOOKUP(AF6,Rubric!$A$93:$C$96,2,FALSE())) | AH6: =IF(COUNT(AE6,AG6)=0,"",SUM(AE6,AG6)) | AI6: 3–4 cluster titles | AJ6: =IF(AI6="","",VLOOKUP(AI6,Rubric!$A$100:$B$102,2,FALSE())) | AK6: 2 channels with distinct uses | AL6: =IF(AK6="","",VLOOKUP(AK6,Rubric!$A$106:$B$108,2,FALSE())) | AM6: =IF(COUNT(AJ6,AL6)=0,"",SUM(AJ6,AL6)) | AN6: =IF($B6="","",SUM(L6,T6,AC6,AH6,AM6)) | AO6: No | AP6: No | AQ6: No | AR6: =IF(OR(W6="",X6=""),"",IF(OR(X6>Rubric!$B$19,Y6<Rubric!$B$18),"VETO","")) | AS6: =IF(AF6="","",IF(VLOOKUP(AF6,Rubric!$A$93:$C$96,3,FALSE())="Yes","VETO","")) | AT6: =IF($B6="","",IF(OR(AO6="Yes",AP6="Yes",AQ6="Yes",AR6="VETO",AS6="VETO"),"VETO","")) | AU6: =IF($B6="","",12-COUNTA(F6,H6,J6,M6,O6,Q6,U6,AA6,AD6,AF6,AI6,AK6)+IF(AND(OR(W6="",X6=""),NOT(AND(W6="",X6=""))),1,0)) | AV6: =IF($B6="","",IF(AT6="VETO","Rejected – veto",IF(AU6>0,"Incomplete ("&AU6&" missing)",IF(AN6>=Rubric!$B$5,"Tier 1 – Approved",IF(AN6>=Rubric!$B$6,"Tier 2 – Watchlist","Tier 3 – Rejected"))))) | AW6: =IF(OR($B6="",AT6="VETO"),"",IF(AU6>0,"",1+SUMPRODUCT(($B$6:$B$60<>"")*($AT$6:$AT$60<>"VETO")*($AU$6:$AU$60=0)*($AN$6:$AN$60>AN6)))) | AY6: Top 3: Gardner Comprehensive BSR ~40k-217k $9.99 100 pages, Beekeeping Journal 60 sheets BSR 1.53M $6.99 145 ratings, Ideal Tracker BSR 889k. Defects: typos, hive # limited, missing queen cells etc. Saturation 12/48 generic. | AZ6: Amazon.com search Oct 7 2026; subagent BSR sampling; category BSR proxies; policy: KDP low-content guidelines.
A7: =IF($B7="","",ROW()-5) | B7: Small Boat & Marine Engine Maintenance Log | C7: Marine / small-craft ownership | D7: Low-content | E7: 46302 | F7: 450000 | G7: =IF(F7="","",VLOOKUP(F7,Rubric!$A$37:$B$40,2,TRUE())) | H7: High – specific problem + buying word | I7: =IF(H7="","",VLOOKUP(H7,Rubric!$A$63:$B$65,2,FALSE())) | J7: Partial – new entrant but weak signals | K7: =IF(J7="","",VLOOKUP(J7,Rubric!$A$69:$B$71,2,FALSE())) | L7: =IF(COUNT(G7,I7,K7)=0,"",SUM(G7,I7,K7)) | M7: 60 | N7: =IF(M7="","",VLOOKUP(M7,Rubric!$A$44:$B$47,2,TRUE())) | O7: Some – 1–2 recurring complaints | P7: =IF(O7="","",VLOOKUP(O7,Rubric!$A$75:$B$77,2,FALSE())) | Q7: 32 | R7: =IF(Q7="","",Q7/Rubric!$B$7) | S7: =IF(R7="","",VLOOKUP(R7,Rubric!$A$51:$B$53,2,TRUE())) | T7: =IF(COUNT(N7,P7,S7)=0,"",SUM(N7,P7,S7)) | U7: 2.8 | V7: =IF(U7="","",VLOOKUP(MAX(U7,0),Rubric!$A$57:$B$59,2,TRUE())) | Y7: =IF(OR(W7="",X7=""),"",IF(AND(W7>=Rubric!$B$8,W7<=Rubric!$B$9),IF(Rubric!$B$13=1,(W7-X7*Rubric!$B$12)*Rubric!$B$10,W7*Rubric!$B$10-X7*Rubric!$B$12),W7*Rubric!$B$11)) | Z7: =IF($B7="","",IF(AND(W7="",X7=""),7,IF(OR(W7="",X7=""),"",IF(X7>Rubric!$B$17,0,IF(AND(Y7>Rubric!$B$14,X7<Rubric!$B$15),7,IF(Y7>Rubric!$B$16,4,0)))))) | AA7: Low – utility log or workbook, <2% | AB7: =IF(AA7="","",VLOOKUP(AA7,Rubric!$A$81:$B$83,2,FALSE())) | AC7: =IF(COUNT(V7,Z7,AB7)=0,"",SUM(V7,Z7,AB7)) | AD7: Full – templatable with the Python generator | AE7: =IF(AD7="","",VLOOKUP(AD7,Rubric!$A$87:$B$89,2,FALSE())) | AF7: Low – logs and forms, little fact-checking | AG7: =IF(AF7="","",VLOOKUP(AF7,Rubric!$A$93:$C$96,2,FALSE())) | AH7: =IF(COUNT(AE7,AG7)=0,"",SUM(AE7,AG7)) | AI7: 3–4 cluster titles | AJ7: =IF(AI7="","",VLOOKUP(AI7,Rubric!$A$100:$B$102,2,FALSE())) | AK7: 2 channels with distinct uses | AL7: =IF(AK7="","",VLOOKUP(AK7,Rubric!$A$106:$B$108,2,FALSE())) | AM7: =IF(COUNT(AJ7,AL7)=0,"",SUM(AJ7,AL7)) | AN7: =IF($B7="","",SUM(L7,T7,AC7,AH7,AM7)) | AR7: =IF(OR(W7="",X7=""),"",IF(OR(X7>Rubric!$B$19,Y7<Rubric!$B$18),"VETO","")) | AS7: =IF(AF7="","",IF(VLOOKUP(AF7,Rubric!$A$93:$C$96,3,FALSE())="Yes","VETO","")) | AT7: =IF($B7="","",IF(OR(AO7="Yes",AP7="Yes",AQ7="Yes",AR7="VETO",AS7="VETO"),"VETO","")) | AU7: =IF($B7="","",12-COUNTA(F7,H7,J7,M7,O7,Q7,U7,AA7,AD7,AF7,AI7,AK7)+IF(AND(OR(W7="",X7=""),NOT(AND(W7="",X7=""))),1,0)) | AV7: =IF($B7="","",IF(AT7="VETO","Rejected – veto",IF(AU7>0,"Incomplete ("&AU7&" missing)",IF(AN7>=Rubric!$B$5,"Tier 1 – Approved",IF(AN7>=Rubric!$B$6,"Tier 2 – Watchlist","Tier 3 – Rejected"))))) | AW7: =IF(OR($B7="",AT7="VETO"),"",IF(AU7>0,"",1+SUMPRODUCT(($B$6:$B$60<>"")*($AT$6:$AT$60<>"VETO")*($AU$6:$AU$60=0)*($AN$6:$AN$60>AN7)))) | AX7: Researching | AY7: BSR top3 ~450000, reviews top10 ~60, generic 32/48. Intent High – specific problem + buying word, freshness Partial – new entrant but weak signals, defect Some – 1–2 recurring complaints. Based on Amazon search sampling Oct 2026, subagent research, and category benchmarks. | AZ7: Amazon.com search Oct 7 2026; subagent BSR sampling; category BSR proxies; policy: KDP low-content guidelines.
A8: =IF($B8="","",ROW()-5) | B8: Middle School Fractions & Decimals Practice Workbook (Grades 5–6) | C8: Math practice / education | D8: Medium-content | E8: 46302 | F8: 350000 | G8: =IF(F8="","",VLOOKUP(F8,Rubric!$A$37:$B$40,2,TRUE())) | H8: High – specific problem + buying word | I8: =IF(H8="","",VLOOKUP(H8,Rubric!$A$63:$B$65,2,FALSE())) | J8: Partial – new entrant but weak signals | K8: =IF(J8="","",VLOOKUP(J8,Rubric!$A$69:$B$71,2,FALSE())) | L8: =IF(COUNT(G8,I8,K8)=0,"",SUM(G8,I8,K8)) | M8: 320 | N8: =IF(M8="","",VLOOKUP(M8,Rubric!$A$44:$B$47,2,TRUE())) | O8: Strong – 3+ recurring complaints (missing features, no answer key) | P8: =IF(O8="","",VLOOKUP(O8,Rubric!$A$75:$B$77,2,FALSE())) | Q8: 18 | R8: =IF(Q8="","",Q8/Rubric!$B$7) | S8: =IF(R8="","",VLOOKUP(R8,Rubric!$A$51:$B$53,2,TRUE())) | T8: =IF(COUNT(N8,P8,S8)=0,"",SUM(N8,P8,S8)) | U8: 3.2 | V8: =IF(U8="","",VLOOKUP(MAX(U8,0),Rubric!$A$57:$B$59,2,TRUE())) | Y8: =IF(OR(W8="",X8=""),"",IF(AND(W8>=Rubric!$B$8,W8<=Rubric!$B$9),IF(Rubric!$B$13=1,(W8-X8*Rubric!$B$12)*Rubric!$B$10,W8*Rubric!$B$10-X8*Rubric!$B$12),W8*Rubric!$B$11)) | Z8: =IF($B8="","",IF(AND(W8="",X8=""),7,IF(OR(W8="",X8=""),"",IF(X8>Rubric!$B$17,0,IF(AND(Y8>Rubric!$B$14,X8<Rubric!$B$15),7,IF(Y8>Rubric!$B$16,4,0)))))) | AA8: Low – utility log or workbook, <2% | AB8: =IF(AA8="","",VLOOKUP(AA8,Rubric!$A$81:$B$83,2,FALSE())) | AC8: =IF(COUNT(V8,Z8,AB8)=0,"",SUM(V8,Z8,AB8)) | AD8: Partial – needs Book Studio or manual content | AE8: =IF(AD8="","",VLOOKUP(AD8,Rubric!$A$87:$B$89,2,FALSE())) | AF8: Medium – how-to / educational accuracy | AG8: =IF(AF8="","",VLOOKUP(AF8,Rubric!$A$93:$C$96,2,FALSE())) | AH8: =IF(COUNT(AE8,AG8)=0,"",SUM(AE8,AG8)) | AI8: 3–4 cluster titles | AJ8: =IF(AI8="","",VLOOKUP(AI8,Rubric!$A$100:$B$102,2,FALSE())) | AK8: 2 channels with distinct uses | AL8: =IF(AK8="","",VLOOKUP(AK8,Rubric!$A$106:$B$108,2,FALSE())) | AM8: =IF(COUNT(AJ8,AL8)=0,"",SUM(AJ8,AL8)) | AN8: =IF($B8="","",SUM(L8,T8,AC8,AH8,AM8)) | AR8: =IF(OR(W8="",X8=""),"",IF(OR(X8>Rubric!$B$19,Y8<Rubric!$B$18),"VETO","")) | AS8: =IF(AF8="","",IF(VLOOKUP(AF8,Rubric!$A$93:$C$96,3,FALSE())="Yes","VETO","")) | AT8: =IF($B8="","",IF(OR(AO8="Yes",AP8="Yes",AQ8="Yes",AR8="VETO",AS8="VETO"),"VETO","")) | AU8: =IF($B8="","",12-COUNTA(F8,H8,J8,M8,O8,Q8,U8,AA8,AD8,AF8,AI8,AK8)+IF(AND(OR(W8="",X8=""),NOT(AND(W8="",X8=""))),1,0)) | AV8: =IF($B8="","",IF(AT8="VETO","Rejected – veto",IF(AU8>0,"Incomplete ("&AU8&" missing)",IF(AN8>=Rubric!$B$5,"Tier 1 – Approved",IF(AN8>=Rubric!$B$6,"Tier 2 – Watchlist","Tier 3 – Rejected"))))) | AW8: =IF(OR($B8="",AT8="VETO"),"",IF(AU8>0,"",1+SUMPRODUCT(($B$6:$B$60<>"")*($AT$6:$AT$60<>"VETO")*($AU$6:$AU$60=0)*($AN$6:$AN$60>AN8)))) | AX8: Researching | AY8: BSR top3 ~350000, reviews top10 ~320, generic 18/48. Intent High – specific problem + buying word, freshness Partial – new entrant but weak signals, defect Strong – 3+ recurring complaints (missing features, no answer key). Based on Amazon search sampling Oct 2026, subagent research, and category benchmarks. | AZ8: Amazon.com search Oct 7 2026; subagent BSR sampling; category BSR proxies; policy: KDP low-content guidelines.
A9: =IF($B9="","",ROW()-5) | B9: Beginner Chess Tactics & Puzzle Workbook | C9: Chess learning / skill practice | D9: Medium-content | E9: 46302 | F9: 300000 | G9: =IF(F9="","",VLOOKUP(F9,Rubric!$A$37:$B$40,2,TRUE())) | H9: Medium – topic with some buying signal | I9: =IF(H9="","",VLOOKUP(H9,Rubric!$A$63:$B$65,2,FALSE())) | J9: Partial – new entrant but weak signals | K9: =IF(J9="","",VLOOKUP(J9,Rubric!$A$69:$B$71,2,FALSE())) | L9: =IF(COUNT(G9,I9,K9)=0,"",SUM(G9,I9,K9)) | M9: 300 | N9: =IF(M9="","",VLOOKUP(M9,Rubric!$A$44:$B$47,2,TRUE())) | O9: Some – 1–2 recurring complaints | P9: =IF(O9="","",VLOOKUP(O9,Rubric!$A$75:$B$77,2,FALSE())) | Q9: 28 | R9: =IF(Q9="","",Q9/Rubric!$B$7) | S9: =IF(R9="","",VLOOKUP(R9,Rubric!$A$51:$B$53,2,TRUE())) | T9: =IF(COUNT(N9,P9,S9)=0,"",SUM(N9,P9,S9)) | U9: 3 | V9: =IF(U9="","",VLOOKUP(MAX(U9,0),Rubric!$A$57:$B$59,2,TRUE())) | Y9: =IF(OR(W9="",X9=""),"",IF(AND(W9>=Rubric!$B$8,W9<=Rubric!$B$9),IF(Rubric!$B$13=1,(W9-X9*Rubric!$B$12)*Rubric!$B$10,W9*Rubric!$B$10-X9*Rubric!$B$12),W9*Rubric!$B$11)) | Z9: =IF($B9="","",IF(AND(W9="",X9=""),7,IF(OR(W9="",X9=""),"",IF(X9>Rubric!$B$17,0,IF(AND(Y9>Rubric!$B$14,X9<Rubric!$B$15),7,IF(Y9>Rubric!$B$16,4,0)))))) | AA9: Low – utility log or workbook, <2% | AB9: =IF(AA9="","",VLOOKUP(AA9,Rubric!$A$81:$B$83,2,FALSE())) | AC9: =IF(COUNT(V9,Z9,AB9)=0,"",SUM(V9,Z9,AB9)) | AD9: Partial – needs Book Studio or manual content | AE9: =IF(AD9="","",VLOOKUP(AD9,Rubric!$A$87:$B$89,2,FALSE())) | AF9: Medium – how-to / educational accuracy | AG9: =IF(AF9="","",VLOOKUP(AF9,Rubric!$A$93:$C$96,2,FALSE())) | AH9: =IF(COUNT(AE9,AG9)=0,"",SUM(AE9,AG9)) | AI9: 2–3 cluster titles | AJ9: =IF(AI9="","",VLOOKUP(AI9,Rubric!$A$100:$B$102,2,FALSE())) | AK9: 1 channel focus | AL9: =IF(AK9="","",VLOOKUP(AK9,Rubric!$A$106:$B$108,2,FALSE())) | AM9: =IF(COUNT(AJ9,AL9)=0,"",SUM(AJ9,AL9)) | AN9: =IF($B9="","",SUM(L9,T9,AC9,AH9,AM9)) | AR9: =IF(OR(W9="",X9=""),"",IF(OR(X9>Rubric!$B$19,Y9<Rubric!$B$18),"VETO","")) | AS9: =IF(AF9="","",IF(VLOOKUP(AF9,Rubric!$A$93:$C$96,3,FALSE())="Yes","VETO","")) | AT9: =IF($B9="","",IF(OR(AO9="Yes",AP9="Yes",AQ9="Yes",AR9="VETO",AS9="VETO"),"VETO","")) | AU9: =IF($B9="","",12-COUNTA(F9,H9,J9,M9,O9,Q9,U9,AA9,AD9,AF9,AI9,AK9)+IF(AND(OR(W9="",X9=""),NOT(AND(W9="",X9=""))),1,0)) | AV9: =IF($B9="","",IF(AT9="VETO","Rejected – veto",IF(AU9>0,"Incomplete ("&AU9&" missing)",IF(AN9>=Rubric!$B$5,"Tier 1 – Approved",IF(AN9>=Rubric!$B$6,"Tier 2 – Watchlist","Tier 3 – Rejected"))))) | AW9: =IF(OR($B9="",AT9="VETO"),"",IF(AU9>0,"",1+SUMPRODUCT(($B$6:$B$60<>"")*($AT$6:$AT$60<>"VETO")*($AU$6:$AU$60=0)*($AN$6:$AN$60>AN9)))) | AX9: Researching | AY9: BSR top3 ~300000, reviews top10 ~300, generic 28/48. Intent Medium – topic with some buying signal, freshness Partial – new entrant but weak signals, defect Some – 1–2 recurring complaints. Based on Amazon search sampling Oct 2026, subagent research, and category benchmarks. | AZ9: Amazon.com search Oct 7 2026; subagent BSR sampling; category BSR proxies; policy: KDP low-content guidelines.
A10: =IF($B10="","",ROW()-5) | B10: Sourdough Starter & Bake Tracking Log | C10: Sourdough / home baking | D10: Low-content | E10: 46302 | F10: 600000 | G10: =IF(F10="","",VLOOKUP(F10,Rubric!$A$37:$B$40,2,TRUE())) | H10: Medium – topic with some buying signal | I10: =IF(H10="","",VLOOKUP(H10,Rubric!$A$63:$B$65,2,FALSE())) | J10: Partial – new entrant but weak signals | K10: =IF(J10="","",VLOOKUP(J10,Rubric!$A$69:$B$71,2,FALSE())) | L10: =IF(COUNT(G10,I10,K10)=0,"",SUM(G10,I10,K10)) | M10: 15 | N10: =IF(M10="","",VLOOKUP(M10,Rubric!$A$44:$B$47,2,TRUE())) | O10: Some – 1–2 recurring complaints | P10: =IF(O10="","",VLOOKUP(O10,Rubric!$A$75:$B$77,2,FALSE())) | Q10: 38 | R10: =IF(Q10="","",Q10/Rubric!$B$7) | S10: =IF(R10="","",VLOOKUP(R10,Rubric!$A$51:$B$53,2,TRUE())) | T10: =IF(COUNT(N10,P10,S10)=0,"",SUM(N10,P10,S10)) | U10: 2.5 | V10: =IF(U10="","",VLOOKUP(MAX(U10,0),Rubric!$A$57:$B$59,2,TRUE())) | Y10: =IF(OR(W10="",X10=""),"",IF(AND(W10>=Rubric!$B$8,W10<=Rubric!$B$9),IF(Rubric!$B$13=1,(W10-X10*Rubric!$B$12)*Rubric!$B$10,W10*Rubric!$B$10-X10*Rubric!$B$12),W10*Rubric!$B$11)) | Z10: =IF($B10="","",IF(AND(W10="",X10=""),7,IF(OR(W10="",X10=""),"",IF(X10>Rubric!$B$17,0,IF(AND(Y10>Rubric!$B$14,X10<Rubric!$B$15),7,IF(Y10>Rubric!$B$16,4,0)))))) | AA10: Low – utility log or workbook, <2% | AB10: =IF(AA10="","",VLOOKUP(AA10,Rubric!$A$81:$B$83,2,FALSE())) | AC10: =IF(COUNT(V10,Z10,AB10)=0,"",SUM(V10,Z10,AB10)) | AD10: Full – templatable with the Python generator | AE10: =IF(AD10="","",VLOOKUP(AD10,Rubric!$A$87:$B$89,2,FALSE())) | AF10: Low – logs and forms, little fact-checking | AG10: =IF(AF10="","",VLOOKUP(AF10,Rubric!$A$93:$C$96,2,FALSE())) | AH10: =IF(COUNT(AE10,AG10)=0,"",SUM(AE10,AG10)) | AI10: 2–3 cluster titles | AJ10: =IF(AI10="","",VLOOKUP(AI10,Rubric!$A$100:$B$102,2,FALSE())) | AK10: 2 channels with distinct uses | AL10: =IF(AK10="","",VLOOKUP(AK10,Rubric!$A$106:$B$108,2,FALSE())) | AM10: =IF(COUNT(AJ10,AL10)=0,"",SUM(AJ10,AL10)) | AN10: =IF($B10="","",SUM(L10,T10,AC10,AH10,AM10)) | AR10: =IF(OR(W10="",X10=""),"",IF(OR(X10>Rubric!$B$19,Y10<Rubric!$B$18),"VETO","")) | AS10: =IF(AF10="","",IF(VLOOKUP(AF10,Rubric!$A$93:$C$96,3,FALSE())="Yes","VETO","")) | AT10: =IF($B10="","",IF(OR(AO10="Yes",AP10="Yes",AQ10="Yes",AR10="VETO",AS10="VETO"),"VETO","")) | AU10: =IF($B10="","",12-COUNTA(F10,H10,J10,M10,O10,Q10,U10,AA10,AD10,AF10,AI10,AK10)+IF(AND(OR(W10="",X10=""),NOT(AND(W10="",X10=""))),1,0)) | AV10: =IF($B10="","",IF(AT10="VETO","Rejected – veto",IF(AU10>0,"Incomplete ("&AU10&" missing)",IF(AN10>=Rubric!$B$5,"Tier 1 – Approved",IF(AN10>=Rubric!$B$6,"Tier 2 – Watchlist","Tier 3 – Rejected"))))) | AW10: =IF(OR($B10="",AT10="VETO"),"",IF(AU10>0,"",1+SUMPRODUCT(($B$6:$B$60<>"")*($AT$6:$AT$60<>"VETO")*($AU$6:$AU$60=0)*($AN$6:$AN$60>AN10)))) | AX10: Researching | AY10: BSR top3 ~600000, reviews top10 ~15, generic 38/48. Intent Medium – topic with some buying signal, freshness Partial – new entrant but weak signals, defect Some – 1–2 recurring complaints. Based on Amazon search sampling Oct 2026, subagent research, and category benchmarks. | AZ10: Amazon.com search Oct 7 2026; subagent BSR sampling; category BSR proxies; policy: KDP low-content guidelines.
A11: =IF($B11="","",ROW()-5) | B11: RV Trip, Inspection & Maintenance Logbook | C11: RV ownership / maintenance | D11: Low-content | E11: 46302 | F11: 250000 | G11: =IF(F11="","",VLOOKUP(F11,Rubric!$A$37:$B$40,2,TRUE())) | H11: High – specific problem + buying word | I11: =IF(H11="","",VLOOKUP(H11,Rubric!$A$63:$B$65,2,FALSE())) | J11: Yes – new entrant <6 mo, <100 reviews, BSR <100k | K11: =IF(J11="","",VLOOKUP(J11,Rubric!$A$69:$B$71,2,FALSE())) | L11: =IF(COUNT(G11,I11,K11)=0,"",SUM(G11,I11,K11)) | M11: 50 | N11: =IF(M11="","",VLOOKUP(M11,Rubric!$A$44:$B$47,2,TRUE())) | O11: Some – 1–2 recurring complaints | P11: =IF(O11="","",VLOOKUP(O11,Rubric!$A$75:$B$77,2,FALSE())) | Q11: 36 | R11: =IF(Q11="","",Q11/Rubric!$B$7) | S11: =IF(R11="","",VLOOKUP(R11,Rubric!$A$51:$B$53,2,TRUE())) | T11: =IF(COUNT(N11,P11,S11)=0,"",SUM(N11,P11,S11)) | U11: 3.1 | V11: =IF(U11="","",VLOOKUP(MAX(U11,0),Rubric!$A$57:$B$59,2,TRUE())) | Y11: =IF(OR(W11="",X11=""),"",IF(AND(W11>=Rubric!$B$8,W11<=Rubric!$B$9),IF(Rubric!$B$13=1,(W11-X11*Rubric!$B$12)*Rubric!$B$10,W11*Rubric!$B$10-X11*Rubric!$B$12),W11*Rubric!$B$11)) | Z11: =IF($B11="","",IF(AND(W11="",X11=""),7,IF(OR(W11="",X11=""),"",IF(X11>Rubric!$B$17,0,IF(AND(Y11>Rubric!$B$14,X11<Rubric!$B$15),7,IF(Y11>Rubric!$B$16,4,0)))))) | AA11: Low – utility log or workbook, <2% | AB11: =IF(AA11="","",VLOOKUP(AA11,Rubric!$A$81:$B$83,2,FALSE())) | AC11: =IF(COUNT(V11,Z11,AB11)=0,"",SUM(V11,Z11,AB11)) | AD11: Full – templatable with the Python generator | AE11: =IF(AD11="","",VLOOKUP(AD11,Rubric!$A$87:$B$89,2,FALSE())) | AF11: Low – logs and forms, little fact-checking | AG11: =IF(AF11="","",VLOOKUP(AF11,Rubric!$A$93:$C$96,2,FALSE())) | AH11: =IF(COUNT(AE11,AG11)=0,"",SUM(AE11,AG11)) | AI11: 3–4 cluster titles | AJ11: =IF(AI11="","",VLOOKUP(AI11,Rubric!$A$100:$B$102,2,FALSE())) | AK11: 2 channels with distinct uses | AL11: =IF(AK11="","",VLOOKUP(AK11,Rubric!$A$106:$B$108,2,FALSE())) | AM11: =IF(COUNT(AJ11,AL11)=0,"",SUM(AJ11,AL11)) | AN11: =IF($B11="","",SUM(L11,T11,AC11,AH11,AM11)) | AR11: =IF(OR(W11="",X11=""),"",IF(OR(X11>Rubric!$B$19,Y11<Rubric!$B$18),"VETO","")) | AS11: =IF(AF11="","",IF(VLOOKUP(AF11,Rubric!$A$93:$C$96,3,FALSE())="Yes","VETO","")) | AT11: =IF($B11="","",IF(OR(AO11="Yes",AP11="Yes",AQ11="Yes",AR11="VETO",AS11="VETO"),"VETO","")) | AU11: =IF($B11="","",12-COUNTA(F11,H11,J11,M11,O11,Q11,U11,AA11,AD11,AF11,AI11,AK11)+IF(AND(OR(W11="",X11=""),NOT(AND(W11="",X11=""))),1,0)) | AV11: =IF($B11="","",IF(AT11="VETO","Rejected – veto",IF(AU11>0,"Incomplete ("&AU11&" missing)",IF(AN11>=Rubric!$B$5,"Tier 1 – Approved",IF(AN11>=Rubric!$B$6,"Tier 2 – Watchlist","Tier 3 – Rejected"))))) | AW11: =IF(OR($B11="",AT11="VETO"),"",IF(AU11>0,"",1+SUMPRODUCT(($B$6:$B$60<>"")*($AT$6:$AT$60<>"VETO")*($AU$6:$AU$60=0)*($AN$6:$AN$60>AN11)))) | AX11: Researching | AY11: BSR top3 ~250000, reviews top10 ~50, generic 36/48. Intent High – specific problem + buying word, freshness Yes – new entrant <6 mo, <100 reviews, BSR <100k, defect Some – 1–2 recurring complaints. Based on Amazon search sampling Oct 2026, subagent research, and category benchmarks. | AZ11: Amazon.com search Oct 7 2026; subagent BSR sampling; category BSR proxies; policy: KDP low-content guidelines.
A12: =IF($B12="","",ROW()-5) | B12: HVAC Service Call & Equipment Maintenance Log | C12: HVAC trade records | D12: Low-content | E12: 46302 | F12: 300000 | G12: =IF(F12="","",VLOOKUP(F12,Rubric!$A$37:$B$40,2,TRUE())) | H12: High – specific problem + buying word | I12: =IF(H12="","",VLOOKUP(H12,Rubric!$A$63:$B$65,2,FALSE())) | J12: Yes – new entrant <6 mo, <100 reviews, BSR <100k | K12: =IF(J12="","",VLOOKUP(J12,Rubric!$A$69:$B$71,2,FALSE())) | L12: =IF(COUNT(G12,I12,K12)=0,"",SUM(G12,I12,K12)) | M12: 4 | N12: =IF(M12="","",VLOOKUP(M12,Rubric!$A$44:$B$47,2,TRUE())) | O12: Strong – 3+ recurring complaints (missing features, no answer key) | P12: =IF(O12="","",VLOOKUP(O12,Rubric!$A$75:$B$77,2,FALSE())) | Q12: 36 | R12: =IF(Q12="","",Q12/Rubric!$B$7) | S12: =IF(R12="","",VLOOKUP(R12,Rubric!$A$51:$B$53,2,TRUE())) | T12: =IF(COUNT(N12,P12,S12)=0,"",SUM(N12,P12,S12)) | U12: 2.9 | V12: =IF(U12="","",VLOOKUP(MAX(U12,0),Rubric!$A$57:$B$59,2,TRUE())) | Y12: =IF(OR(W12="",X12=""),"",IF(AND(W12>=Rubric!$B$8,W12<=Rubric!$B$9),IF(Rubric!$B$13=1,(W12-X12*Rubric!$B$12)*Rubric!$B$10,W12*Rubric!$B$10-X12*Rubric!$B$12),W12*Rubric!$B$11)) | Z12: =IF($B12="","",IF(AND(W12="",X12=""),7,IF(OR(W12="",X12=""),"",IF(X12>Rubric!$B$17,0,IF(AND(Y12>Rubric!$B$14,X12<Rubric!$B$15),7,IF(Y12>Rubric!$B$16,4,0)))))) | AA12: Low – utility log or workbook, <2% | AB12: =IF(AA12="","",VLOOKUP(AA12,Rubric!$A$81:$B$83,2,FALSE())) | AC12: =IF(COUNT(V12,Z12,AB12)=0,"",SUM(V12,Z12,AB12)) | AD12: Full – templatable with the Python generator | AE12: =IF(AD12="","",VLOOKUP(AD12,Rubric!$A$87:$B$89,2,FALSE())) | AF12: Low – logs and forms, little fact-checking | AG12: =IF(AF12="","",VLOOKUP(AF12,Rubric!$A$93:$C$96,2,FALSE())) | AH12: =IF(COUNT(AE12,AG12)=0,"",SUM(AE12,AG12)) | AI12: 3–4 cluster titles | AJ12: =IF(AI12="","",VLOOKUP(AI12,Rubric!$A$100:$B$102,2,FALSE())) | AK12: 2 channels with distinct uses | AL12: =IF(AK12="","",VLOOKUP(AK12,Rubric!$A$106:$B$108,2,FALSE())) | AM12: =IF(COUNT(AJ12,AL12)=0,"",SUM(AJ12,AL12)) | AN12: =IF($B12="","",SUM(L12,T12,AC12,AH12,AM12)) | AR12: =IF(OR(W12="",X12=""),"",IF(OR(X12>Rubric!$B$19,Y12<Rubric!$B$18),"VETO","")) | AS12: =IF(AF12="","",IF(VLOOKUP(AF12,Rubric!$A$93:$C$96,3,FALSE())="Yes","VETO","")) | AT12: =IF($B12="","",IF(OR(AO12="Yes",AP12="Yes",AQ12="Yes",AR12="VETO",AS12="VETO"),"VETO","")) | AU12: =IF($B12="","",12-COUNTA(F12,H12,J12,M12,O12,Q12,U12,AA12,AD12,AF12,AI12,AK12)+IF(AND(OR(W12="",X12=""),NOT(AND(W12="",X12=""))),1,0)) | AV12: =IF($B12="","",IF(AT12="VETO","Rejected – veto",IF(AU12>0,"Incomplete ("&AU12&" missing)",IF(AN12>=Rubric!$B$5,"Tier 1 – Approved",IF(AN12>=Rubric!$B$6,"Tier 2 – Watchlist","Tier 3 – Rejected"))))) | AW12: =IF(OR($B12="",AT12="VETO"),"",IF(AU12>0,"",1+SUMPRODUCT(($B$6:$B$60<>"")*($AT$6:$AT$60<>"VETO")*($AU$6:$AU$60=0)*($AN$6:$AN$60>AN12)))) | AX12: Researching | AY12: BSR top3 ~300000, reviews top10 ~4, generic 36/48. Intent High – specific problem + buying word, freshness Yes – new entrant <6 mo, <100 reviews, BSR <100k, defect Strong – 3+ recurring complaints (missing features, no answer key). Based on Amazon search sampling Oct 2026, subagent research, and category benchmarks. | AZ12: Amazon.com search Oct 7 2026; subagent BSR sampling; category BSR proxies; policy: KDP low-content guidelines.
A13: =IF($B13="","",ROW()-5) | B13: Road Trip Activity Book for Kids Ages 8–12 | C13: Family travel / children's activities | D13: Medium-content | E13: 46302 | F13: 45000 | G13: =IF(F13="","",VLOOKUP(F13,Rubric!$A$37:$B$40,2,TRUE())) | H13: High – specific problem + buying word | I13: =IF(H13="","",VLOOKUP(H13,Rubric!$A$63:$B$65,2,FALSE())) | J13: Yes – new entrant <6 mo, <100 reviews, BSR <100k | K13: =IF(J13="","",VLOOKUP(J13,Rubric!$A$69:$B$71,2,FALSE())) | L13: =IF(COUNT(G13,I13,K13)=0,"",SUM(G13,I13,K13)) | M13: 200 | N13: =IF(M13="","",VLOOKUP(M13,Rubric!$A$44:$B$47,2,TRUE())) | O13: Some – 1–2 recurring complaints | P13: =IF(O13="","",VLOOKUP(O13,Rubric!$A$75:$B$77,2,FALSE())) | Q13: 22 | R13: =IF(Q13="","",Q13/Rubric!$B$7) | S13: =IF(R13="","",VLOOKUP(R13,Rubric!$A$51:$B$53,2,TRUE())) | T13: =IF(COUNT(N13,P13,S13)=0,"",SUM(N13,P13,S13)) | U13: 3.4 | V13: =IF(U13="","",VLOOKUP(MAX(U13,0),Rubric!$A$57:$B$59,2,TRUE())) | Y13: =IF(OR(W13="",X13=""),"",IF(AND(W13>=Rubric!$B$8,W13<=Rubric!$B$9),IF(Rubric!$B$13=1,(W13-X13*Rubric!$B$12)*Rubric!$B$10,W13*Rubric!$B$10-X13*Rubric!$B$12),W13*Rubric!$B$11)) | Z13: =IF($B13="","",IF(AND(W13="",X13=""),7,IF(OR(W13="",X13=""),"",IF(X13>Rubric!$B$17,0,IF(AND(Y13>Rubric!$B$14,X13<Rubric!$B$15),7,IF(Y13>Rubric!$B$16,4,0)))))) | AA13: Medium – 2–4% | AB13: =IF(AA13="","",VLOOKUP(AA13,Rubric!$A$81:$B$83,2,FALSE())) | AC13: =IF(COUNT(V13,Z13,AB13)=0,"",SUM(V13,Z13,AB13)) | AD13: Partial – needs Book Studio or manual content | AE13: =IF(AD13="","",VLOOKUP(AD13,Rubric!$A$87:$B$89,2,FALSE())) | AF13: Medium – how-to / educational accuracy | AG13: =IF(AF13="","",VLOOKUP(AF13,Rubric!$A$93:$C$96,2,FALSE())) | AH13: =IF(COUNT(AE13,AG13)=0,"",SUM(AE13,AG13)) | AI13: 2–3 cluster titles | AJ13: =IF(AI13="","",VLOOKUP(AI13,Rubric!$A$100:$B$102,2,FALSE())) | AK13: 2 channels with distinct uses | AL13: =IF(AK13="","",VLOOKUP(AK13,Rubric!$A$106:$B$108,2,FALSE())) | AM13: =IF(COUNT(AJ13,AL13)=0,"",SUM(AJ13,AL13)) | AN13: =IF($B13="","",SUM(L13,T13,AC13,AH13,AM13)) | AR13: =IF(OR(W13="",X13=""),"",IF(OR(X13>Rubric!$B$19,Y13<Rubric!$B$18),"VETO","")) | AS13: =IF(AF13="","",IF(VLOOKUP(AF13,Rubric!$A$93:$C$96,3,FALSE())="Yes","VETO","")) | AT13: =IF($B13="","",IF(OR(AO13="Yes",AP13="Yes",AQ13="Yes",AR13="VETO",AS13="VETO"),"VETO","")) | AU13: =IF($B13="","",12-COUNTA(F13,H13,J13,M13,O13,Q13,U13,AA13,AD13,AF13,AI13,AK13)+IF(AND(OR(W13="",X13=""),NOT(AND(W13="",X13=""))),1,0)) | AV13: =IF($B13="","",IF(AT13="VETO","Rejected – veto",IF(AU13>0,"Incomplete ("&AU13&" missing)",IF(AN13>=Rubric!$B$5,"Tier 1 – Approved",IF(AN13>=Rubric!$B$6,"Tier 2 – Watchlist","Tier 3 – Rejected"))))) | AW13: =IF(OR($B13="",AT13="VETO"),"",IF(AU13>0,"",1+SUMPRODUCT(($B$6:$B$60<>"")*($AT$6:$AT$60<>"VETO")*($AU$6:$AU$60=0)*($AN$6:$AN$60>AN13)))) | AX13: Researching | AY13: BSR top3 ~45000, reviews top10 ~200, generic 22/48. Intent High – specific problem + buying word, freshness Yes – new entrant <6 mo, <100 reviews, BSR <100k, defect Some – 1–2 recurring complaints. Based on Amazon search sampling Oct 2026, subagent research, and category benchmarks. | AZ13: Amazon.com search Oct 7 2026; subagent BSR sampling; category BSR proxies; policy: KDP low-content guidelines.
A14: =IF($B14="","",ROW()-5) | B14: First-Time Homeowner Seasonal Maintenance Playbook | C14: First-time homeownership | D14: Flagship | E14: 46302 | F14: 80000 | G14: =IF(F14="","",VLOOKUP(F14,Rubric!$A$37:$B$40,2,TRUE())) | H14: High – specific problem + buying word | I14: =IF(H14="","",VLOOKUP(H14,Rubric!$A$63:$B$65,2,FALSE())) | J14: Partial – new entrant but weak signals | K14: =IF(J14="","",VLOOKUP(J14,Rubric!$A$69:$B$71,2,FALSE())) | L14: =IF(COUNT(G14,I14,K14)=0,"",SUM(G14,I14,K14)) | M14: 180 | N14: =IF(M14="","",VLOOKUP(M14,Rubric!$A$44:$B$47,2,TRUE())) | O14: Some – 1–2 recurring complaints | P14: =IF(O14="","",VLOOKUP(O14,Rubric!$A$75:$B$77,2,FALSE())) | Q14: 32 | R14: =IF(Q14="","",Q14/Rubric!$B$7) | S14: =IF(R14="","",VLOOKUP(R14,Rubric!$A$51:$B$53,2,TRUE())) | T14: =IF(COUNT(N14,P14,S14)=0,"",SUM(N14,P14,S14)) | U14: 4.5 | V14: =IF(U14="","",VLOOKUP(MAX(U14,0),Rubric!$A$57:$B$59,2,TRUE())) | Y14: =IF(OR(W14="",X14=""),"",IF(AND(W14>=Rubric!$B$8,W14<=Rubric!$B$9),IF(Rubric!$B$13=1,(W14-X14*Rubric!$B$12)*Rubric!$B$10,W14*Rubric!$B$10-X14*Rubric!$B$12),W14*Rubric!$B$11)) | Z14: =IF($B14="","",IF(AND(W14="",X14=""),7,IF(OR(W14="",X14=""),"",IF(X14>Rubric!$B$17,0,IF(AND(Y14>Rubric!$B$14,X14<Rubric!$B$15),7,IF(Y14>Rubric!$B$16,4,0)))))) | AA14: Low – utility log or workbook, <2% | AB14: =IF(AA14="","",VLOOKUP(AA14,Rubric!$A$81:$B$83,2,FALSE())) | AC14: =IF(COUNT(V14,Z14,AB14)=0,"",SUM(V14,Z14,AB14)) | AD14: Low – custom illustration or heavy manual work | AE14: =IF(AD14="","",VLOOKUP(AD14,Rubric!$A$87:$B$89,2,FALSE())) | AF14: Medium – how-to / educational accuracy | AG14: =IF(AF14="","",VLOOKUP(AF14,Rubric!$A$93:$C$96,2,FALSE())) | AH14: =IF(COUNT(AE14,AG14)=0,"",SUM(AE14,AG14)) | AI14: 5+ cluster titles | AJ14: =IF(AI14="","",VLOOKUP(AI14,Rubric!$A$100:$B$102,2,FALSE())) | AK14: 3+ channels with distinct uses | AL14: =IF(AK14="","",VLOOKUP(AK14,Rubric!$A$106:$B$108,2,FALSE())) | AM14: =IF(COUNT(AJ14,AL14)=0,"",SUM(AJ14,AL14)) | AN14: =IF($B14="","",SUM(L14,T14,AC14,AH14,AM14)) | AR14: =IF(OR(W14="",X14=""),"",IF(OR(X14>Rubric!$B$19,Y14<Rubric!$B$18),"VETO","")) | AS14: =IF(AF14="","",IF(VLOOKUP(AF14,Rubric!$A$93:$C$96,3,FALSE())="Yes","VETO","")) | AT14: =IF($B14="","",IF(OR(AO14="Yes",AP14="Yes",AQ14="Yes",AR14="VETO",AS14="VETO"),"VETO","")) | AU14: =IF($B14="","",12-COUNTA(F14,H14,J14,M14,O14,Q14,U14,AA14,AD14,AF14,AI14,AK14)+IF(AND(OR(W14="",X14=""),NOT(AND(W14="",X14=""))),1,0)) | AV14: =IF($B14="","",IF(AT14="VETO","Rejected – veto",IF(AU14>0,"Incomplete ("&AU14&" missing)",IF(AN14>=Rubric!$B$5,"Tier 1 – Approved",IF(AN14>=Rubric!$B$6,"Tier 2 – Watchlist","Tier 3 – Rejected"))))) | AW14: =IF(OR($B14="",AT14="VETO"),"",IF(AU14>0,"",1+SUMPRODUCT(($B$6:$B$60<>"")*($AT$6:$AT$60<>"VETO")*($AU$6:$AU$60=0)*($AN$6:$AN$60>AN14)))) | AX14: Researching | AY14: BSR top3 ~80000, reviews top10 ~180, generic 32/48. Intent High – specific problem + buying word, freshness Partial – new entrant but weak signals, defect Some – 1–2 recurring complaints. Based on Amazon search sampling Oct 2026, subagent research, and category benchmarks. | AZ14: Amazon.com search Oct 7 2026; subagent BSR sampling; category BSR proxies; policy: KDP low-content guidelines.
A15: =IF($B15="","",ROW()-5) | B15: Backyard Birdwatching Field Guide for Beginners | C15: Backyard birding / nature learning | D15: Digital-first eBook | E15: 46302 | F15: 15000 | G15: =IF(F15="","",VLOOKUP(F15,Rubric!$A$37:$B$40,2,TRUE())) | H15: High – specific problem + buying word | I15: =IF(H15="","",VLOOKUP(H15,Rubric!$A$63:$B$65,2,FALSE())) | J15: No – no recent entrants | K15: =IF(J15="","",VLOOKUP(J15,Rubric!$A$69:$B$71,2,FALSE())) | L15: =IF(COUNT(G15,I15,K15)=0,"",SUM(G15,I15,K15)) | M15: 400 | N15: =IF(M15="","",VLOOKUP(M15,Rubric!$A$44:$B$47,2,TRUE())) | O15: Some – 1–2 recurring complaints | P15: =IF(O15="","",VLOOKUP(O15,Rubric!$A$75:$B$77,2,FALSE())) | Q15: 15 | R15: =IF(Q15="","",Q15/Rubric!$B$7) | S15: =IF(R15="","",VLOOKUP(R15,Rubric!$A$51:$B$53,2,TRUE())) | T15: =IF(COUNT(N15,P15,S15)=0,"",SUM(N15,P15,S15)) | U15: 2 | V15: =IF(U15="","",VLOOKUP(MAX(U15,0),Rubric!$A$57:$B$59,2,TRUE())) | Y15: =IF(OR(W15="",X15=""),"",IF(AND(W15>=Rubric!$B$8,W15<=Rubric!$B$9),IF(Rubric!$B$13=1,(W15-X15*Rubric!$B$12)*Rubric!$B$10,W15*Rubric!$B$10-X15*Rubric!$B$12),W15*Rubric!$B$11)) | Z15: =IF($B15="","",IF(AND(W15="",X15=""),7,IF(OR(W15="",X15=""),"",IF(X15>Rubric!$B$17,0,IF(AND(Y15>Rubric!$B$14,X15<Rubric!$B$15),7,IF(Y15>Rubric!$B$16,4,0)))))) | AA15: Low – utility log or workbook, <2% | AB15: =IF(AA15="","",VLOOKUP(AA15,Rubric!$A$81:$B$83,2,FALSE())) | AC15: =IF(COUNT(V15,Z15,AB15)=0,"",SUM(V15,Z15,AB15)) | AD15: Low – custom illustration or heavy manual work | AE15: =IF(AD15="","",VLOOKUP(AD15,Rubric!$A$87:$B$89,2,FALSE())) | AF15: High – research-intensive, fact-checking heavy | AG15: =IF(AF15="","",VLOOKUP(AF15,Rubric!$A$93:$C$96,2,FALSE())) | AH15: =IF(COUNT(AE15,AG15)=0,"",SUM(AE15,AG15)) | AI15: 3–4 cluster titles | AJ15: =IF(AI15="","",VLOOKUP(AI15,Rubric!$A$100:$B$102,2,FALSE())) | AK15: 2 channels with distinct uses | AL15: =IF(AK15="","",VLOOKUP(AK15,Rubric!$A$106:$B$108,2,FALSE())) | AM15: =IF(COUNT(AJ15,AL15)=0,"",SUM(AJ15,AL15)) | AN15: =IF($B15="","",SUM(L15,T15,AC15,AH15,AM15)) | AR15: =IF(OR(W15="",X15=""),"",IF(OR(X15>Rubric!$B$19,Y15<Rubric!$B$18),"VETO","")) | AS15: =IF(AF15="","",IF(VLOOKUP(AF15,Rubric!$A$93:$C$96,3,FALSE())="Yes","VETO","")) | AT15: =IF($B15="","",IF(OR(AO15="Yes",AP15="Yes",AQ15="Yes",AR15="VETO",AS15="VETO"),"VETO","")) | AU15: =IF($B15="","",12-COUNTA(F15,H15,J15,M15,O15,Q15,U15,AA15,AD15,AF15,AI15,AK15)+IF(AND(OR(W15="",X15=""),NOT(AND(W15="",X15=""))),1,0)) | AV15: =IF($B15="","",IF(AT15="VETO","Rejected – veto",IF(AU15>0,"Incomplete ("&AU15&" missing)",IF(AN15>=Rubric!$B$5,"Tier 1 – Approved",IF(AN15>=Rubric!$B$6,"Tier 2 – Watchlist","Tier 3 – Rejected"))))) | AW15: =IF(OR($B15="",AT15="VETO"),"",IF(AU15>0,"",1+SUMPRODUCT(($B$6:$B$60<>"")*($AT$6:$AT$60<>"VETO")*($AU$6:$AU$60=0)*($AN$6:$AN$60>AN15)))) | AX15: Researching | AY15: BSR top3 ~15000, reviews top10 ~400, generic 15/48. Intent High – specific problem + buying word, freshness No – no recent entrants, defect Some – 1–2 recurring complaints. Based on Amazon search sampling Oct 2026, subagent research, and category benchmarks. | AZ15: Amazon.com search Oct 7 2026; subagent BSR sampling; category BSR proxies; policy: KDP low-content guidelines.
A16: =IF($B16="","",ROW()-5) | B16: Rental Property Turnover & Maintenance Log | C16: Rental property operations | D16: Low-content | E16: 46302 | F16: 500000 | G16: =IF(F16="","",VLOOKUP(F16,Rubric!$A$37:$B$40,2,TRUE())) | H16: Medium – topic with some buying signal | I16: =IF(H16="","",VLOOKUP(H16,Rubric!$A$63:$B$65,2,FALSE())) | J16: No – no recent entrants | K16: =IF(J16="","",VLOOKUP(J16,Rubric!$A$69:$B$71,2,FALSE())) | L16: =IF(COUNT(G16,I16,K16)=0,"",SUM(G16,I16,K16)) | M16: 20 | N16: =IF(M16="","",VLOOKUP(M16,Rubric!$A$44:$B$47,2,TRUE())) | O16: Some – 1–2 recurring complaints | P16: =IF(O16="","",VLOOKUP(O16,Rubric!$A$75:$B$77,2,FALSE())) | Q16: 36 | R16: =IF(Q16="","",Q16/Rubric!$B$7) | S16: =IF(R16="","",VLOOKUP(R16,Rubric!$A$51:$B$53,2,TRUE())) | T16: =IF(COUNT(N16,P16,S16)=0,"",SUM(N16,P16,S16)) | U16: 2.9 | V16: =IF(U16="","",VLOOKUP(MAX(U16,0),Rubric!$A$57:$B$59,2,TRUE())) | Y16: =IF(OR(W16="",X16=""),"",IF(AND(W16>=Rubric!$B$8,W16<=Rubric!$B$9),IF(Rubric!$B$13=1,(W16-X16*Rubric!$B$12)*Rubric!$B$10,W16*Rubric!$B$10-X16*Rubric!$B$12),W16*Rubric!$B$11)) | Z16: =IF($B16="","",IF(AND(W16="",X16=""),7,IF(OR(W16="",X16=""),"",IF(X16>Rubric!$B$17,0,IF(AND(Y16>Rubric!$B$14,X16<Rubric!$B$15),7,IF(Y16>Rubric!$B$16,4,0)))))) | AA16: Low – utility log or workbook, <2% | AB16: =IF(AA16="","",VLOOKUP(AA16,Rubric!$A$81:$B$83,2,FALSE())) | AC16: =IF(COUNT(V16,Z16,AB16)=0,"",SUM(V16,Z16,AB16)) | AD16: Full – templatable with the Python generator | AE16: =IF(AD16="","",VLOOKUP(AD16,Rubric!$A$87:$B$89,2,FALSE())) | AF16: Low – logs and forms, little fact-checking | AG16: =IF(AF16="","",VLOOKUP(AF16,Rubric!$A$93:$C$96,2,FALSE())) | AH16: =IF(COUNT(AE16,AG16)=0,"",SUM(AE16,AG16)) | AI16: 3–4 cluster titles | AJ16: =IF(AI16="","",VLOOKUP(AI16,Rubric!$A$100:$B$102,2,FALSE())) | AK16: 2 channels with distinct uses | AL16: =IF(AK16="","",VLOOKUP(AK16,Rubric!$A$106:$B$108,2,FALSE())) | AM16: =IF(COUNT(AJ16,AL16)=0,"",SUM(AJ16,AL16)) | AN16: =IF($B16="","",SUM(L16,T16,AC16,AH16,AM16)) | AR16: =IF(OR(W16="",X16=""),"",IF(OR(X16>Rubric!$B$19,Y16<Rubric!$B$18),"VETO","")) | AS16: =IF(AF16="","",IF(VLOOKUP(AF16,Rubric!$A$93:$C$96,3,FALSE())="Yes","VETO","")) | AT16: =IF($B16="","",IF(OR(AO16="Yes",AP16="Yes",AQ16="Yes",AR16="VETO",AS16="VETO"),"VETO","")) | AU16: =IF($B16="","",12-COUNTA(F16,H16,J16,M16,O16,Q16,U16,AA16,AD16,AF16,AI16,AK16)+IF(AND(OR(W16="",X16=""),NOT(AND(W16="",X16=""))),1,0)) | AV16: =IF($B16="","",IF(AT16="VETO","Rejected – veto",IF(AU16>0,"Incomplete ("&AU16&" missing)",IF(AN16>=Rubric!$B$5,"Tier 1 – Approved",IF(AN16>=Rubric!$B$6,"Tier 2 – Watchlist","Tier 3 – Rejected"))))) | AW16: =IF(OR($B16="",AT16="VETO"),"",IF(AU16>0,"",1+SUMPRODUCT(($B$6:$B$60<>"")*($AT$6:$AT$60<>"VETO")*($AU$6:$AU$60=0)*($AN$6:$AN$60>AN16)))) | AY16: BSR top3 ~500000, reviews top10 ~20, generic 36/48. Intent Medium – topic with some buying signal, freshness No – no recent entrants, defect Some – 1–2 recurring complaints. Based on Amazon search sampling Oct 2026, subagent research, and category benchmarks. | AZ16: Amazon.com search Oct 7 2026; subagent BSR sampling; category BSR proxies; policy: KDP low-content guidelines.
A17: =IF($B17="","",ROW()-5) | B17: Small Fleet Vehicle Maintenance Log | C17: Fleet / vehicle operations | D17: Low-content | E17: 46302 | F17: 600000 | G17: =IF(F17="","",VLOOKUP(F17,Rubric!$A$37:$B$40,2,TRUE())) | H17: Medium – topic with some buying signal | I17: =IF(H17="","",VLOOKUP(H17,Rubric!$A$63:$B$65,2,FALSE())) | J17: No – no recent entrants | K17: =IF(J17="","",VLOOKUP(J17,Rubric!$A$69:$B$71,2,FALSE())) | L17: =IF(COUNT(G17,I17,K17)=0,"",SUM(G17,I17,K17)) | M17: 250 | N17: =IF(M17="","",VLOOKUP(M17,Rubric!$A$44:$B$47,2,TRUE())) | O17: None – no recurring defect | P17: =IF(O17="","",VLOOKUP(O17,Rubric!$A$75:$B$77,2,FALSE())) | Q17: 38 | R17: =IF(Q17="","",Q17/Rubric!$B$7) | S17: =IF(R17="","",VLOOKUP(R17,Rubric!$A$51:$B$53,2,TRUE())) | T17: =IF(COUNT(N17,P17,S17)=0,"",SUM(N17,P17,S17)) | U17: 2.8 | V17: =IF(U17="","",VLOOKUP(MAX(U17,0),Rubric!$A$57:$B$59,2,TRUE())) | Y17: =IF(OR(W17="",X17=""),"",IF(AND(W17>=Rubric!$B$8,W17<=Rubric!$B$9),IF(Rubric!$B$13=1,(W17-X17*Rubric!$B$12)*Rubric!$B$10,W17*Rubric!$B$10-X17*Rubric!$B$12),W17*Rubric!$B$11)) | Z17: =IF($B17="","",IF(AND(W17="",X17=""),7,IF(OR(W17="",X17=""),"",IF(X17>Rubric!$B$17,0,IF(AND(Y17>Rubric!$B$14,X17<Rubric!$B$15),7,IF(Y17>Rubric!$B$16,4,0)))))) | AA17: Low – utility log or workbook, <2% | AB17: =IF(AA17="","",VLOOKUP(AA17,Rubric!$A$81:$B$83,2,FALSE())) | AC17: =IF(COUNT(V17,Z17,AB17)=0,"",SUM(V17,Z17,AB17)) | AD17: Full – templatable with the Python generator | AE17: =IF(AD17="","",VLOOKUP(AD17,Rubric!$A$87:$B$89,2,FALSE())) | AF17: Low – logs and forms, little fact-checking | AG17: =IF(AF17="","",VLOOKUP(AF17,Rubric!$A$93:$C$96,2,FALSE())) | AH17: =IF(COUNT(AE17,AG17)=0,"",SUM(AE17,AG17)) | AI17: 2–3 cluster titles | AJ17: =IF(AI17="","",VLOOKUP(AI17,Rubric!$A$100:$B$102,2,FALSE())) | AK17: 1 channel focus | AL17: =IF(AK17="","",VLOOKUP(AK17,Rubric!$A$106:$B$108,2,FALSE())) | AM17: =IF(COUNT(AJ17,AL17)=0,"",SUM(AJ17,AL17)) | AN17: =IF($B17="","",SUM(L17,T17,AC17,AH17,AM17)) | AR17: =IF(OR(W17="",X17=""),"",IF(OR(X17>Rubric!$B$19,Y17<Rubric!$B$18),"VETO","")) | AS17: =IF(AF17="","",IF(VLOOKUP(AF17,Rubric!$A$93:$C$96,3,FALSE())="Yes","VETO","")) | AT17: =IF($B17="","",IF(OR(AO17="Yes",AP17="Yes",AQ17="Yes",AR17="VETO",AS17="VETO"),"VETO","")) | AU17: =IF($B17="","",12-COUNTA(F17,H17,J17,M17,O17,Q17,U17,AA17,AD17,AF17,AI17,AK17)+IF(AND(OR(W17="",X17=""),NOT(AND(W17="",X17=""))),1,0)) | AV17: =IF($B17="","",IF(AT17="VETO","Rejected – veto",IF(AU17>0,"Incomplete ("&AU17&" missing)",IF(AN17>=Rubric!$B$5,"Tier 1 – Approved",IF(AN17>=Rubric!$B$6,"Tier 2 – Watchlist","Tier 3 – Rejected"))))) | AW17: =IF(OR($B17="",AT17="VETO"),"",IF(AU17>0,"",1+SUMPRODUCT(($B$6:$B$60<>"")*($AT$6:$AT$60<>"VETO")*($AU$6:$AU$60=0)*($AN$6:$AN$60>AN17)))) | AY17: BSR top3 ~600000, reviews top10 ~250, generic 38/48. Intent Medium – topic with some buying signal, freshness No – no recent entrants, defect None – no recurring defect. Based on Amazon search sampling Oct 2026, subagent research, and category benchmarks. | AZ17: Amazon.com search Oct 7 2026; subagent BSR sampling; category BSR proxies; policy: KDP low-content guidelines.
A18: =IF($B18="","",ROW()-5) | B18: Motorcycle Maintenance & Service Log | C18: Motorcycle ownership | D18: Low-content | E18: 46302 | F18: 700000 | G18: =IF(F18="","",VLOOKUP(F18,Rubric!$A$37:$B$40,2,TRUE())) | H18: Medium – topic with some buying signal | I18: =IF(H18="","",VLOOKUP(H18,Rubric!$A$63:$B$65,2,FALSE())) | J18: No – no recent entrants | K18: =IF(J18="","",VLOOKUP(J18,Rubric!$A$69:$B$71,2,FALSE())) | L18: =IF(COUNT(G18,I18,K18)=0,"",SUM(G18,I18,K18)) | M18: 30 | N18: =IF(M18="","",VLOOKUP(M18,Rubric!$A$44:$B$47,2,TRUE())) | O18: None – no recurring defect | P18: =IF(O18="","",VLOOKUP(O18,Rubric!$A$75:$B$77,2,FALSE())) | Q18: 35 | R18: =IF(Q18="","",Q18/Rubric!$B$7) | S18: =IF(R18="","",VLOOKUP(R18,Rubric!$A$51:$B$53,2,TRUE())) | T18: =IF(COUNT(N18,P18,S18)=0,"",SUM(N18,P18,S18)) | U18: 2.7 | V18: =IF(U18="","",VLOOKUP(MAX(U18,0),Rubric!$A$57:$B$59,2,TRUE())) | Y18: =IF(OR(W18="",X18=""),"",IF(AND(W18>=Rubric!$B$8,W18<=Rubric!$B$9),IF(Rubric!$B$13=1,(W18-X18*Rubric!$B$12)*Rubric!$B$10,W18*Rubric!$B$10-X18*Rubric!$B$12),W18*Rubric!$B$11)) | Z18: =IF($B18="","",IF(AND(W18="",X18=""),7,IF(OR(W18="",X18=""),"",IF(X18>Rubric!$B$17,0,IF(AND(Y18>Rubric!$B$14,X18<Rubric!$B$15),7,IF(Y18>Rubric!$B$16,4,0)))))) | AA18: Low – utility log or workbook, <2% | AB18: =IF(AA18="","",VLOOKUP(AA18,Rubric!$A$81:$B$83,2,FALSE())) | AC18: =IF(COUNT(V18,Z18,AB18)=0,"",SUM(V18,Z18,AB18)) | AD18: Full – templatable with the Python generator | AE18: =IF(AD18="","",VLOOKUP(AD18,Rubric!$A$87:$B$89,2,FALSE())) | AF18: Low – logs and forms, little fact-checking | AG18: =IF(AF18="","",VLOOKUP(AF18,Rubric!$A$93:$C$96,2,FALSE())) | AH18: =IF(COUNT(AE18,AG18)=0,"",SUM(AE18,AG18)) | AI18: 2–3 cluster titles | AJ18: =IF(AI18="","",VLOOKUP(AI18,Rubric!$A$100:$B$102,2,FALSE())) | AK18: 1 channel focus | AL18: =IF(AK18="","",VLOOKUP(AK18,Rubric!$A$106:$B$108,2,FALSE())) | AM18: =IF(COUNT(AJ18,AL18)=0,"",SUM(AJ18,AL18)) | AN18: =IF($B18="","",SUM(L18,T18,AC18,AH18,AM18)) | AR18: =IF(OR(W18="",X18=""),"",IF(OR(X18>Rubric!$B$19,Y18<Rubric!$B$18),"VETO","")) | AS18: =IF(AF18="","",IF(VLOOKUP(AF18,Rubric!$A$93:$C$96,3,FALSE())="Yes","VETO","")) | AT18: =IF($B18="","",IF(OR(AO18="Yes",AP18="Yes",AQ18="Yes",AR18="VETO",AS18="VETO"),"VETO","")) | AU18: =IF($B18="","",12-COUNTA(F18,H18,J18,M18,O18,Q18,U18,AA18,AD18,AF18,AI18,AK18)+IF(AND(OR(W18="",X18=""),NOT(AND(W18="",X18=""))),1,0)) | AV18: =IF($B18="","",IF(AT18="VETO","Rejected – veto",IF(AU18>0,"Incomplete ("&AU18&" missing)",IF(AN18>=Rubric!$B$5,"Tier 1 – Approved",IF(AN18>=Rubric!$B$6,"Tier 2 – Watchlist","Tier 3 – Rejected"))))) | AW18: =IF(OR($B18="",AT18="VETO"),"",IF(AU18>0,"",1+SUMPRODUCT(($B$6:$B$60<>"")*($AT$6:$AT$60<>"VETO")*($AU$6:$AU$60=0)*($AN$6:$AN$60>AN18)))) | AY18: BSR top3 ~700000, reviews top10 ~30, generic 35/48. Intent Medium – topic with some buying signal, freshness No – no recent entrants, defect None – no recurring defect. Based on Amazon search sampling Oct 2026, subagent research, and category benchmarks. | AZ18: Amazon.com search Oct 7 2026; subagent BSR sampling; category BSR proxies; policy: KDP low-content guidelines.
A19: =IF($B19="","",ROW()-5) | B19: Poultry Flock & Egg Production Record Book | C19: Backyard poultry / smallholding | D19: Low-content | E19: 46302 | F19: 276000 | G19: =IF(F19="","",VLOOKUP(F19,Rubric!$A$37:$B$40,2,TRUE())) | H19: High – specific problem + buying word | I19: =IF(H19="","",VLOOKUP(H19,Rubric!$A$63:$B$65,2,FALSE())) | J19: Yes – new entrant <6 mo, <100 reviews, BSR <100k | K19: =IF(J19="","",VLOOKUP(J19,Rubric!$A$69:$B$71,2,FALSE())) | L19: =IF(COUNT(G19,I19,K19)=0,"",SUM(G19,I19,K19)) | M19: 120 | N19: =IF(M19="","",VLOOKUP(M19,Rubric!$A$44:$B$47,2,TRUE())) | O19: Some – 1–2 recurring complaints | P19: =IF(O19="","",VLOOKUP(O19,Rubric!$A$75:$B$77,2,FALSE())) | Q19: 40 | R19: =IF(Q19="","",Q19/Rubric!$B$7) | S19: =IF(R19="","",VLOOKUP(R19,Rubric!$A$51:$B$53,2,TRUE())) | T19: =IF(COUNT(N19,P19,S19)=0,"",SUM(N19,P19,S19)) | U19: 2.9 | V19: =IF(U19="","",VLOOKUP(MAX(U19,0),Rubric!$A$57:$B$59,2,TRUE())) | Y19: =IF(OR(W19="",X19=""),"",IF(AND(W19>=Rubric!$B$8,W19<=Rubric!$B$9),IF(Rubric!$B$13=1,(W19-X19*Rubric!$B$12)*Rubric!$B$10,W19*Rubric!$B$10-X19*Rubric!$B$12),W19*Rubric!$B$11)) | Z19: =IF($B19="","",IF(AND(W19="",X19=""),7,IF(OR(W19="",X19=""),"",IF(X19>Rubric!$B$17,0,IF(AND(Y19>Rubric!$B$14,X19<Rubric!$B$15),7,IF(Y19>Rubric!$B$16,4,0)))))) | AA19: Low – utility log or workbook, <2% | AB19: =IF(AA19="","",VLOOKUP(AA19,Rubric!$A$81:$B$83,2,FALSE())) | AC19: =IF(COUNT(V19,Z19,AB19)=0,"",SUM(V19,Z19,AB19)) | AD19: Full – templatable with the Python generator | AE19: =IF(AD19="","",VLOOKUP(AD19,Rubric!$A$87:$B$89,2,FALSE())) | AF19: Low – logs and forms, little fact-checking | AG19: =IF(AF19="","",VLOOKUP(AF19,Rubric!$A$93:$C$96,2,FALSE())) | AH19: =IF(COUNT(AE19,AG19)=0,"",SUM(AE19,AG19)) | AI19: 3–4 cluster titles | AJ19: =IF(AI19="","",VLOOKUP(AI19,Rubric!$A$100:$B$102,2,FALSE())) | AK19: 2 channels with distinct uses | AL19: =IF(AK19="","",VLOOKUP(AK19,Rubric!$A$106:$B$108,2,FALSE())) | AM19: =IF(COUNT(AJ19,AL19)=0,"",SUM(AJ19,AL19)) | AN19: =IF($B19="","",SUM(L19,T19,AC19,AH19,AM19)) | AR19: =IF(OR(W19="",X19=""),"",IF(OR(X19>Rubric!$B$19,Y19<Rubric!$B$18),"VETO","")) | AS19: =IF(AF19="","",IF(VLOOKUP(AF19,Rubric!$A$93:$C$96,3,FALSE())="Yes","VETO","")) | AT19: =IF($B19="","",IF(OR(AO19="Yes",AP19="Yes",AQ19="Yes",AR19="VETO",AS19="VETO"),"VETO","")) | AU19: =IF($B19="","",12-COUNTA(F19,H19,J19,M19,O19,Q19,U19,AA19,AD19,AF19,AI19,AK19)+IF(AND(OR(W19="",X19=""),NOT(AND(W19="",X19=""))),1,0)) | AV19: =IF($B19="","",IF(AT19="VETO","Rejected – veto",IF(AU19>0,"Incomplete ("&AU19&" missing)",IF(AN19>=Rubric!$B$5,"Tier 1 – Approved",IF(AN19>=Rubric!$B$6,"Tier 2 – Watchlist","Tier 3 – Rejected"))))) | AW19: =IF(OR($B19="",AT19="VETO"),"",IF(AU19>0,"",1+SUMPRODUCT(($B$6:$B$60<>"")*($AT$6:$AT$60<>"VETO")*($AU$6:$AU$60=0)*($AN$6:$AN$60>AN19)))) | AY19: BSR top3 ~276000, reviews top10 ~120, generic 40/48. Intent High – specific problem + buying word, freshness Yes – new entrant <6 mo, <100 reviews, BSR <100k, defect Some – 1–2 recurring complaints. Based on Amazon search sampling Oct 2026, subagent research, and category benchmarks. | AZ19: Amazon.com search Oct 7 2026; subagent BSR sampling; category BSR proxies; policy: KDP low-content guidelines.
A20: =IF($B20="","",ROW()-5) | B20: Vegetable Garden Planting & Harvest Log | C20: Home gardening / crop records | D20: Low-content | E20: 46302 | F20: 200000 | G20: =IF(F20="","",VLOOKUP(F20,Rubric!$A$37:$B$40,2,TRUE())) | H20: High – specific problem + buying word | I20: =IF(H20="","",VLOOKUP(H20,Rubric!$A$63:$B$65,2,FALSE())) | J20: Partial – new entrant but weak signals | K20: =IF(J20="","",VLOOKUP(J20,Rubric!$A$69:$B$71,2,FALSE())) | L20: =IF(COUNT(G20,I20,K20)=0,"",SUM(G20,I20,K20)) | M20: 180 | N20: =IF(M20="","",VLOOKUP(M20,Rubric!$A$44:$B$47,2,TRUE())) | O20: Some – 1–2 recurring complaints | P20: =IF(O20="","",VLOOKUP(O20,Rubric!$A$75:$B$77,2,FALSE())) | Q20: 35 | R20: =IF(Q20="","",Q20/Rubric!$B$7) | S20: =IF(R20="","",VLOOKUP(R20,Rubric!$A$51:$B$53,2,TRUE())) | T20: =IF(COUNT(N20,P20,S20)=0,"",SUM(N20,P20,S20)) | U20: 3 | V20: =IF(U20="","",VLOOKUP(MAX(U20,0),Rubric!$A$57:$B$59,2,TRUE())) | Y20: =IF(OR(W20="",X20=""),"",IF(AND(W20>=Rubric!$B$8,W20<=Rubric!$B$9),IF(Rubric!$B$13=1,(W20-X20*Rubric!$B$12)*Rubric!$B$10,W20*Rubric!$B$10-X20*Rubric!$B$12),W20*Rubric!$B$11)) | Z20: =IF($B20="","",IF(AND(W20="",X20=""),7,IF(OR(W20="",X20=""),"",IF(X20>Rubric!$B$17,0,IF(AND(Y20>Rubric!$B$14,X20<Rubric!$B$15),7,IF(Y20>Rubric!$B$16,4,0)))))) | AA20: Low – utility log or workbook, <2% | AB20: =IF(AA20="","",VLOOKUP(AA20,Rubric!$A$81:$B$83,2,FALSE())) | AC20: =IF(COUNT(V20,Z20,AB20)=0,"",SUM(V20,Z20,AB20)) | AD20: Full – templatable with the Python generator | AE20: =IF(AD20="","",VLOOKUP(AD20,Rubric!$A$87:$B$89,2,FALSE())) | AF20: Low – logs and forms, little fact-checking | AG20: =IF(AF20="","",VLOOKUP(AF20,Rubric!$A$93:$C$96,2,FALSE())) | AH20: =IF(COUNT(AE20,AG20)=0,"",SUM(AE20,AG20)) | AI20: 3–4 cluster titles | AJ20: =IF(AI20="","",VLOOKUP(AI20,Rubric!$A$100:$B$102,2,FALSE())) | AK20: 2 channels with distinct uses | AL20: =IF(AK20="","",VLOOKUP(AK20,Rubric!$A$106:$B$108,2,FALSE())) | AM20: =IF(COUNT(AJ20,AL20)=0,"",SUM(AJ20,AL20)) | AN20: =IF($B20="","",SUM(L20,T20,AC20,AH20,AM20)) | AR20: =IF(OR(W20="",X20=""),"",IF(OR(X20>Rubric!$B$19,Y20<Rubric!$B$18),"VETO","")) | AS20: =IF(AF20="","",IF(VLOOKUP(AF20,Rubric!$A$93:$C$96,3,FALSE())="Yes","VETO","")) | AT20: =IF($B20="","",IF(OR(AO20="Yes",AP20="Yes",AQ20="Yes",AR20="VETO",AS20="VETO"),"VETO","")) | AU20: =IF($B20="","",12-COUNTA(F20,H20,J20,M20,O20,Q20,U20,AA20,AD20,AF20,AI20,AK20)+IF(AND(OR(W20="",X20=""),NOT(AND(W20="",X20=""))),1,0)) | AV20: =IF($B20="","",IF(AT20="VETO","Rejected – veto",IF(AU20>0,"Incomplete ("&AU20&" missing)",IF(AN20>=Rubric!$B$5,"Tier 1 – Approved",IF(AN20>=Rubric!$B$6,"Tier 2 – Watchlist","Tier 3 – Rejected"))))) | AW20: =IF(OR($B20="",AT20="VETO"),"",IF(AU20>0,"",1+SUMPRODUCT(($B$6:$B$60<>"")*($AT$6:$AT$60<>"VETO")*($AU$6:$AU$60=0)*($AN$6:$AN$60>AN20)))) | AY20: BSR top3 ~200000, reviews top10 ~180, generic 35/48. Intent High – specific problem + buying word, freshness Partial – new entrant but weak signals, defect Some – 1–2 recurring complaints. Based on Amazon search sampling Oct 2026, subagent research, and category benchmarks. | AZ20: Amazon.com search Oct 7 2026; subagent BSR sampling; category BSR proxies; policy: KDP low-content guidelines.
A21: =IF($B21="","",ROW()-5) | B21: Aquarium Maintenance & Water-Parameter Log | C21: Aquarium keeping | D21: Low-content | E21: 46302 | F21: 773000 | G21: =IF(F21="","",VLOOKUP(F21,Rubric!$A$37:$B$40,2,TRUE())) | H21: Low – vague, gift or inspirational | I21: =IF(H21="","",VLOOKUP(H21,Rubric!$A$63:$B$65,2,FALSE())) | J21: No – no recent entrants | K21: =IF(J21="","",VLOOKUP(J21,Rubric!$A$69:$B$71,2,FALSE())) | L21: =IF(COUNT(G21,I21,K21)=0,"",SUM(G21,I21,K21)) | M21: 8 | N21: =IF(M21="","",VLOOKUP(M21,Rubric!$A$44:$B$47,2,TRUE())) | O21: None – no recurring defect | P21: =IF(O21="","",VLOOKUP(O21,Rubric!$A$75:$B$77,2,FALSE())) | Q21: 42 | R21: =IF(Q21="","",Q21/Rubric!$B$7) | S21: =IF(R21="","",VLOOKUP(R21,Rubric!$A$51:$B$53,2,TRUE())) | T21: =IF(COUNT(N21,P21,S21)=0,"",SUM(N21,P21,S21)) | U21: 2.5 | V21: =IF(U21="","",VLOOKUP(MAX(U21,0),Rubric!$A$57:$B$59,2,TRUE())) | Y21: =IF(OR(W21="",X21=""),"",IF(AND(W21>=Rubric!$B$8,W21<=Rubric!$B$9),IF(Rubric!$B$13=1,(W21-X21*Rubric!$B$12)*Rubric!$B$10,W21*Rubric!$B$10-X21*Rubric!$B$12),W21*Rubric!$B$11)) | Z21: =IF($B21="","",IF(AND(W21="",X21=""),7,IF(OR(W21="",X21=""),"",IF(X21>Rubric!$B$17,0,IF(AND(Y21>Rubric!$B$14,X21<Rubric!$B$15),7,IF(Y21>Rubric!$B$16,4,0)))))) | AA21: Low – utility log or workbook, <2% | AB21: =IF(AA21="","",VLOOKUP(AA21,Rubric!$A$81:$B$83,2,FALSE())) | AC21: =IF(COUNT(V21,Z21,AB21)=0,"",SUM(V21,Z21,AB21)) | AD21: Full – templatable with the Python generator | AE21: =IF(AD21="","",VLOOKUP(AD21,Rubric!$A$87:$B$89,2,FALSE())) | AF21: Low – logs and forms, little fact-checking | AG21: =IF(AF21="","",VLOOKUP(AF21,Rubric!$A$93:$C$96,2,FALSE())) | AH21: =IF(COUNT(AE21,AG21)=0,"",SUM(AE21,AG21)) | AI21: 1–2 cluster titles | AJ21: =IF(AI21="","",VLOOKUP(AI21,Rubric!$A$100:$B$102,2,FALSE())) | AK21: 1 channel focus | AL21: =IF(AK21="","",VLOOKUP(AK21,Rubric!$A$106:$B$108,2,FALSE())) | AM21: =IF(COUNT(AJ21,AL21)=0,"",SUM(AJ21,AL21)) | AN21: =IF($B21="","",SUM(L21,T21,AC21,AH21,AM21)) | AR21: =IF(OR(W21="",X21=""),"",IF(OR(X21>Rubric!$B$19,Y21<Rubric!$B$18),"VETO","")) | AS21: =IF(AF21="","",IF(VLOOKUP(AF21,Rubric!$A$93:$C$96,3,FALSE())="Yes","VETO","")) | AT21: =IF($B21="","",IF(OR(AO21="Yes",AP21="Yes",AQ21="Yes",AR21="VETO",AS21="VETO"),"VETO","")) | AU21: =IF($B21="","",12-COUNTA(F21,H21,J21,M21,O21,Q21,U21,AA21,AD21,AF21,AI21,AK21)+IF(AND(OR(W21="",X21=""),NOT(AND(W21="",X21=""))),1,0)) | AV21: =IF($B21="","",IF(AT21="VETO","Rejected – veto",IF(AU21>0,"Incomplete ("&AU21&" missing)",IF(AN21>=Rubric!$B$5,"Tier 1 – Approved",IF(AN21>=Rubric!$B$6,"Tier 2 – Watchlist","Tier 3 – Rejected"))))) | AW21: =IF(OR($B21="",AT21="VETO"),"",IF(AU21>0,"",1+SUMPRODUCT(($B$6:$B$60<>"")*($AT$6:$AT$60<>"VETO")*($AU$6:$AU$60=0)*($AN$6:$AN$60>AN21)))) | AY21: BSR top3 ~773000, reviews top10 ~8, generic 42/48. Intent Low – vague, gift or inspirational, freshness No – no recent entrants, defect None – no recurring defect. Based on Amazon search sampling Oct 2026, subagent research, and category benchmarks. | AZ21: Amazon.com search Oct 7 2026; subagent BSR sampling; category BSR proxies; policy: KDP low-content guidelines.
